<?xml version='1.0'?>
<sdf version='1.11'>
  <model name='mecanum-wheel'>
	<!-- keep static for now -->
    <static>false</static>

	<link name='mecanum-base'>
	  <pose>0 0 0 0 0 0</pose>
	  <visual name='mb-v'>
	    <geometry>
		  <cylinder>
		    <radius>0.015</radius>
			<length>0.01</length>
		  </cylinder>
		</geometry>
	  </visual>
	  <collision name='mb-c'>
	    <geometry>
		  <cylinder>
		    <radius>0.015</radius>
			<length>0.01</length>
		  </cylinder>
		</geometry>
	  </collision>
	</link>

	<link name='mw-l1'>
	  <pose>0 0 0.03 0 0 -0.785</pose>
      <inertial>
        <mass>0.00113845</mass>
        <inertia>
          <ixx>2.53776e-08</ixx>
          <ixy>0</ixy>
          <ixz>0</ixz>
          <iyy>2.53776e-08</iyy>
          <iyz>0</iyz>
          <izz>1.47666e-08</izz>
        </inertia>
        <pose frame=''>0 0 0 0 -0 0</pose>
      </inertial>
      <self_collide>0</self_collide>
      <kinematic>0</kinematic>
	  <visual name='mw-l1-v'>
	  	<geometry>
		  <mesh>
		    <uri>file://mecanum-roller.stl</uri>
			<scale>0.001 0.001 0.001</scale>
		  </mesh>
		</geometry>
	  </visual>
	  <collision name='mw-l1-c'>
	  	<geometry>
		  <mesh>
		    <uri>file://mecanum-roller.stl</uri>
			<scale>0.001 0.001 0.001</scale>
		  </mesh>
		</geometry>
        <surface>
          <friction>
            <ode>
              <mu>{0}</mu>
              <mu2>{1}</mu2>
              <fdir1>0 0 0</fdir1>
              <slip1>{2}</slip1>
              <slip2>{3}</slip2>
            </ode>
            <torsional>
              <coefficient>{4}</coefficient>
              <patch_radius>0</patch_radius>
              <surface_radius>0</surface_radius>
              <use_patch_radius>1</use_patch_radius>
              <ode>
                <slip>{5}</slip>
              </ode>
            </torsional>
          </friction>
          <bounce>
            <restitution_coefficient>{6}</restitution_coefficient>
            <threshold>{7}</threshold>
          </bounce>
          <contact>
            <collide_without_contact>0</collide_without_contact>
            <collide_without_contact_bitmask>1</collide_without_contact_bitmask>
            <collide_bitmask>1</collide_bitmask>
            <ode>
              <soft_cfm>{8}</soft_cfm>
              <soft_erp>{9}</soft_erp>
              <kp>{10}</kp>
              <kd>{11}</kd>
              <max_vel>0.01</max_vel>
              <min_depth>0</min_depth>
            </ode>
            <bullet>
              <split_impulse>1</split_impulse>
              <split_impulse_penetration_threshold>-0.01</split_impulse_penetration_threshold>
              <soft_cfm>{8}</soft_cfm>
              <soft_erp>{9}</soft_erp>
              <kp>{10}</kp>
              <kd>{11}</kd>
            </bullet>
          </contact>
        </surface>
	  </collision>
	</link>

	<link name='mw-l2'>
	  <pose>0.0212 0 0.0212 -0.615 0.5235 -0.9553</pose>
	  <visual name='mw-l2-v'>
	  	<geometry>
		  <mesh>
		    <uri>file://mecanum-roller.stl</uri>
			<scale>0.001 0.001 0.001</scale>
		  </mesh>
		</geometry>
	  </visual>
	  <collision name='mw-l2-c'>
	  	<geometry>
		  <mesh>
		    <uri>file://mecanum-roller.stl</uri>
			<scale>0.001 0.001 0.001</scale>
		  </mesh>
		</geometry>
        <surface>
          <friction>
            <ode>
              <mu>{0}</mu>
              <mu2>{1}</mu2>
              <fdir1>0 0 0</fdir1>
              <slip1>{2}</slip1>
              <slip2>{3}</slip2>
            </ode>
            <torsional>
              <coefficient>{4}</coefficient>
              <patch_radius>0</patch_radius>
              <surface_radius>0</surface_radius>
              <use_patch_radius>1</use_patch_radius>
              <ode>
                <slip>{5}</slip>
              </ode>
            </torsional>
          </friction>
          <bounce>
            <restitution_coefficient>{6}</restitution_coefficient>
            <threshold>{7}</threshold>
          </bounce>
          <contact>
            <collide_without_contact>0</collide_without_contact>
            <collide_without_contact_bitmask>1</collide_without_contact_bitmask>
            <collide_bitmask>1</collide_bitmask>
            <ode>
              <soft_cfm>{8}</soft_cfm>
              <soft_erp>{9}</soft_erp>
              <kp>{10}</kp>
              <kd>{11}</kd>
              <max_vel>0.01</max_vel>
              <min_depth>0</min_depth>
            </ode>
            <bullet>
              <split_impulse>1</split_impulse>
              <split_impulse_penetration_threshold>-0.01</split_impulse_penetration_threshold>
              <soft_cfm>{8}</soft_cfm>
              <soft_erp>{9}</soft_erp>
              <kp>{10}</kp>
              <kd>{11}</kd>
            </bullet>
          </contact>
        </surface>
	  </collision>
	</link>

	<link name='mw-l3'>
	  <pose>0.03 0 0 -1.5707 1.178 -1.5707</pose>
	  <visual name='mw-l3-v'>
	  	<geometry>
		  <mesh>
		    <uri>file://mecanum-roller.stl</uri>
			<scale>0.001 0.001 0.001</scale>
		  </mesh>
		</geometry>
	  </visual>
	  <collision name='mw-l3-c'>
	  	<geometry>
		  <mesh>
		    <uri>file://mecanum-roller.stl</uri>
			<scale>0.001 0.001 0.001</scale>
		  </mesh>
		</geometry>
        <surface>
          <friction>
            <ode>
              <mu>{0}</mu>
              <mu2>{1}</mu2>
              <fdir1>0 0 0</fdir1>
              <slip1>{2}</slip1>
              <slip2>{3}</slip2>
            </ode>
            <torsional>
              <coefficient>{4}</coefficient>
              <patch_radius>0</patch_radius>
              <surface_radius>0</surface_radius>
              <use_patch_radius>1</use_patch_radius>
              <ode>
                <slip>{5}</slip>
              </ode>
            </torsional>
          </friction>
          <bounce>
            <restitution_coefficient>{6}</restitution_coefficient>
            <threshold>{7}</threshold>
          </bounce>
          <contact>
            <collide_without_contact>0</collide_without_contact>
            <collide_without_contact_bitmask>1</collide_without_contact_bitmask>
            <collide_bitmask>1</collide_bitmask>
            <ode>
              <soft_cfm>{8}</soft_cfm>
              <soft_erp>{9}</soft_erp>
              <kp>{10}</kp>
              <kd>{11}</kd>
              <max_vel>0.01</max_vel>
              <min_depth>0</min_depth>
            </ode>
            <bullet>
              <split_impulse>1</split_impulse>
              <split_impulse_penetration_threshold>-0.01</split_impulse_penetration_threshold>
              <soft_cfm>{8}</soft_cfm>
              <soft_erp>{9}</soft_erp>
              <kp>{10}</kp>
              <kd>{11}</kd>
            </bullet>
          </contact>
        </surface>
	  </collision>
	</link>

	<link name='mw-l4'>
	  <pose>0.0212 0 -0.0212 -2.7761 0.7119 -2.6116</pose>
	  <visual name='mw-l4-v'>
	  	<geometry>
		  <mesh>
		    <uri>file://mecanum-roller.stl</uri>
			<scale>0.001 0.001 0.001</scale>
		  </mesh>
		</geometry>
	  </visual>
	  <collision name='mw-l4-c'>
	  	<geometry>
		  <mesh>
		    <uri>file://mecanum-roller.stl</uri>
			<scale>0.001 0.001 0.001</scale>
		  </mesh>
		</geometry>
        <surface>
          <friction>
            <ode>
              <mu>{0}</mu>
              <mu2>{1}</mu2>
              <fdir1>0 0 0</fdir1>
              <slip1>{2}</slip1>
              <slip2>{3}</slip2>
            </ode>
            <torsional>
              <coefficient>{4}</coefficient>
              <patch_radius>0</patch_radius>
              <surface_radius>0</surface_radius>
              <use_patch_radius>1</use_patch_radius>
              <ode>
                <slip>{5}</slip>
              </ode>
            </torsional>
          </friction>
          <bounce>
            <restitution_coefficient>{6}</restitution_coefficient>
            <threshold>{7}</threshold>
          </bounce>
          <contact>
            <collide_without_contact>0</collide_without_contact>
            <collide_without_contact_bitmask>1</collide_without_contact_bitmask>
            <collide_bitmask>1</collide_bitmask>
            <ode>
              <soft_cfm>{8}</soft_cfm>
              <soft_erp>{9}</soft_erp>
              <kp>{10}</kp>
              <kd>{11}</kd>
              <max_vel>0.01</max_vel>
              <min_depth>0</min_depth>
            </ode>
            <bullet>
              <split_impulse>1</split_impulse>
              <split_impulse_penetration_threshold>-0.01</split_impulse_penetration_threshold>
              <soft_cfm>{8}</soft_cfm>
              <soft_erp>{9}</soft_erp>
              <kp>{10}</kp>
              <kd>{11}</kd>
            </bullet>
          </contact>
        </surface>
	  </collision>
	</link>

	<link name='mw-l5'>
	  <pose>0 0 -0.03 0 0 -2.7488</pose>
	  <visual name='mw-l5-v'>
	  	<geometry>
		  <mesh>
		    <uri>file://mecanum-roller.stl</uri>
			<scale>0.001 0.001 0.001</scale>
		  </mesh>
		</geometry>
	  </visual>
	  <collision name='mw-l5-c'>
	  	<geometry>
		  <mesh>
		    <uri>file://mecanum-roller.stl</uri>
			<scale>0.001 0.001 0.001</scale>
		  </mesh>
		</geometry>
        <surface>
          <friction>
            <ode>
              <mu>{0}</mu>
              <mu2>{1}</mu2>
              <fdir1>0 0 0</fdir1>
              <slip1>{2}</slip1>
              <slip2>{3}</slip2>
            </ode>
            <torsional>
              <coefficient>{4}</coefficient>
              <patch_radius>0</patch_radius>
              <surface_radius>0</surface_radius>
              <use_patch_radius>1</use_patch_radius>
              <ode>
                <slip>{5}</slip>
              </ode>
            </torsional>
          </friction>
          <bounce>
            <restitution_coefficient>{6}</restitution_coefficient>
            <threshold>{7}</threshold>
          </bounce>
          <contact>
            <collide_without_contact>0</collide_without_contact>
            <collide_without_contact_bitmask>1</collide_without_contact_bitmask>
            <collide_bitmask>1</collide_bitmask>
            <ode>
              <soft_cfm>{8}</soft_cfm>
              <soft_erp>{9}</soft_erp>
              <kp>{10}</kp>
              <kd>{11}</kd>
              <max_vel>0.01</max_vel>
              <min_depth>0</min_depth>
            </ode>
            <bullet>
              <split_impulse>1</split_impulse>
              <split_impulse_penetration_threshold>-0.01</split_impulse_penetration_threshold>
              <soft_cfm>{8}</soft_cfm>
              <soft_erp>{9}</soft_erp>
              <kp>{10}</kp>
              <kd>{11}</kd>
            </bullet>
          </contact>
        </surface>
	  </collision>
	</link>

	<link name='mw-l6'>
	  <pose>-0.0212 0 -0.0212 2.776 -0.7119 -2.6117</pose>
	  <visual name='mw-l6-v'>
	  	<geometry>
		  <mesh>
		    <uri>file://mecanum-roller.stl</uri>
			<scale>0.001 0.001 0.001</scale>
		  </mesh>
		</geometry>
	  </visual>
	  <collision name='mw-l6-c'>
	  	<geometry>
		  <mesh>
		    <uri>file://mecanum-roller.stl</uri>
			<scale>0.001 0.001 0.001</scale>
		  </mesh>
		</geometry>
        <surface>
          <friction>
            <ode>
              <mu>{0}</mu>
              <mu2>{1}</mu2>
              <fdir1>0 0 0</fdir1>
              <slip1>{2}</slip1>
              <slip2>{3}</slip2>
            </ode>
            <torsional>
              <coefficient>{4}</coefficient>
              <patch_radius>0</patch_radius>
              <surface_radius>0</surface_radius>
              <use_patch_radius>1</use_patch_radius>
              <ode>
                <slip>{5}</slip>
              </ode>
            </torsional>
          </friction>
          <bounce>
            <restitution_coefficient>{6}</restitution_coefficient>
            <threshold>{7}</threshold>
          </bounce>
          <contact>
            <collide_without_contact>0</collide_without_contact>
            <collide_without_contact_bitmask>1</collide_without_contact_bitmask>
            <collide_bitmask>1</collide_bitmask>
            <ode>
              <soft_cfm>{8}</soft_cfm>
              <soft_erp>{9}</soft_erp>
              <kp>{10}</kp>
              <kd>{11}</kd>
              <max_vel>0.01</max_vel>
              <min_depth>0</min_depth>
            </ode>
            <bullet>
              <split_impulse>1</split_impulse>
              <split_impulse_penetration_threshold>-0.01</split_impulse_penetration_threshold>
              <soft_cfm>{8}</soft_cfm>
              <soft_erp>{9}</soft_erp>
              <kp>{10}</kp>
              <kd>{11}</kd>
            </bullet>
          </contact>
        </surface>
	  </collision>
	</link>

	<link name='mw-l7'>
	  <pose>-0.03 0 0 1.5707 -1.17809 -1.5707</pose>
	  <visual name='mw-l7-v'>
	  	<geometry>
		  <mesh>
		    <uri>file://mecanum-roller.stl</uri>
			<scale>0.001 0.001 0.001</scale>
		  </mesh>
		</geometry>
	  </visual>
	  <collision name='mw-l7-c'>
	  	<geometry>
		  <mesh>
		    <uri>file://mecanum-roller.stl</uri>
			<scale>0.001 0.001 0.001</scale>
		  </mesh>
		</geometry>
        <surface>
          <friction>
            <ode>
              <mu>{0}</mu>
              <mu2>{1}</mu2>
              <fdir1>0 0 0</fdir1>
              <slip1>{2}</slip1>
              <slip2>{3}</slip2>
            </ode>
            <torsional>
              <coefficient>{4}</coefficient>
              <patch_radius>0</patch_radius>
              <surface_radius>0</surface_radius>
              <use_patch_radius>1</use_patch_radius>
              <ode>
                <slip>{5}</slip>
              </ode>
            </torsional>
          </friction>
          <bounce>
            <restitution_coefficient>{6}</restitution_coefficient>
            <threshold>{7}</threshold>
          </bounce>
          <contact>
            <collide_without_contact>0</collide_without_contact>
            <collide_without_contact_bitmask>1</collide_without_contact_bitmask>
            <collide_bitmask>1</collide_bitmask>
            <ode>
              <soft_cfm>{8}</soft_cfm>
              <soft_erp>{9}</soft_erp>
              <kp>{10}</kp>
              <kd>{11}</kd>
              <max_vel>0.01</max_vel>
              <min_depth>0</min_depth>
            </ode>
            <bullet>
              <split_impulse>1</split_impulse>
              <split_impulse_penetration_threshold>-0.01</split_impulse_penetration_threshold>
              <soft_cfm>{8}</soft_cfm>
              <soft_erp>{9}</soft_erp>
              <kp>{10}</kp>
              <kd>{11}</kd>
            </bullet>
          </contact>
        </surface>
	  </collision>
	</link>

	<link name='mw-l8'>
	  <pose>-0.0212 0 0.0212 0.3654 -0.7119 -0.5299</pose>
	  <visual name='mw-l8-v'>
	  	<geometry>
		  <mesh>
		    <uri>file://mecanum-roller.stl</uri>
			<scale>0.001 0.001 0.001</scale>
		  </mesh>
		</geometry>
	  </visual>
	  <collision name='mw-l8-c'>
	  	<geometry>
		  <mesh>
		    <uri>file://mecanum-roller.stl</uri>
			<scale>0.001 0.001 0.001</scale>
		  </mesh>
		</geometry>
        <surface>
          <friction>
            <ode>
              <mu>{0}</mu>
              <mu2>{1}</mu2>
              <fdir1>0 0 0</fdir1>
              <slip1>{2}</slip1>
              <slip2>{3}</slip2>
            </ode>
            <torsional>
              <coefficient>{4}</coefficient>
              <patch_radius>0</patch_radius>
              <surface_radius>0</surface_radius>
              <use_patch_radius>1</use_patch_radius>
              <ode>
                <slip>{5}</slip>
              </ode>
            </torsional>
          </friction>
          <bounce>
            <restitution_coefficient>{6}</restitution_coefficient>
            <threshold>{7}</threshold>
          </bounce>
          <contact>
            <collide_without_contact>0</collide_without_contact>
            <collide_without_contact_bitmask>1</collide_without_contact_bitmask>
            <collide_bitmask>1</collide_bitmask>
            <ode>
              <soft_cfm>{8}</soft_cfm>
              <soft_erp>{9}</soft_erp>
              <kp>{10}</kp>
              <kd>{11}</kd>
              <max_vel>0.01</max_vel>
              <min_depth>0</min_depth>
            </ode>
            <bullet>
              <split_impulse>1</split_impulse>
              <split_impulse_penetration_threshold>-0.01</split_impulse_penetration_threshold>
              <soft_cfm>{8}</soft_cfm>
              <soft_erp>{9}</soft_erp>
              <kp>{10}</kp>
              <kd>{11}</kd>
            </bullet>
          </contact>
        </surface>
	  </collision>
	</link>

	<!-- NOTE: Joint rotations are expressed in parent frame -->
	<joint name='mw-j1' type='revolute'>
	  <pose>0 0 0 0 0 0</pose>
	  <parent>mecanum-base</parent>
	  <child>mw-l1</child>
	  <axis>
	    <xyz>0 1 0</xyz>
        <use_parent_model_frame>0</use_parent_model_frame>
        <limit>
          <lower>-1.79769e+308</lower>
          <upper>1.79769e+308</upper>
          <effort>-1</effort>
          <velocity>-1</velocity>
        </limit>
        <dynamics>
          <spring_reference>0</spring_reference>
          <spring_stiffness>0</spring_stiffness>
          <damping>0</damping>
          <friction>0</friction>
        </dynamics>
	  </axis>
      <physics>
        <ode>
          <limit>
            <cfm>0</cfm>
            <erp>0.2</erp>
          </limit>
          <suspension>
            <cfm>0</cfm>
            <erp>0.2</erp>
          </suspension>
        </ode>
      </physics>
	</joint>

	<joint name='mw-j2' type='revolute'>
	  <pose>0 0 0 0 0 0</pose>
	  <parent>mecanum-base</parent>
	  <child>mw-l2</child>
	  <axis>
	    <xyz>0 1 0</xyz>
        <use_parent_model_frame>0</use_parent_model_frame>
        <limit>
          <lower>-1.79769e+308</lower>
          <upper>1.79769e+308</upper>
          <effort>-1</effort>
          <velocity>-1</velocity>
        </limit>
        <dynamics>
          <spring_reference>0</spring_reference>
          <spring_stiffness>0</spring_stiffness>
          <damping>0</damping>
          <friction>0</friction>
        </dynamics>
	  </axis>
      <physics>
        <ode>
          <limit>
            <cfm>0</cfm>
            <erp>0.2</erp>
          </limit>
          <suspension>
            <cfm>0</cfm>
            <erp>0.2</erp>
          </suspension>
        </ode>
      </physics>
	</joint>

	<joint name='mw-j3' type='revolute'>
	  <pose>0 0 0 0 0 0</pose>
	  <parent>mecanum-base</parent>
	  <child>mw-l3</child>
	  <axis>
	    <xyz>0 1 0</xyz>
        <use_parent_model_frame>0</use_parent_model_frame>
        <limit>
          <lower>-1.79769e+308</lower>
          <upper>1.79769e+308</upper>
          <effort>-1</effort>
          <velocity>-1</velocity>
        </limit>
        <dynamics>
          <spring_reference>0</spring_reference>
          <spring_stiffness>0</spring_stiffness>
          <damping>0</damping>
          <friction>0</friction>
        </dynamics>
	  </axis>
      <physics>
        <ode>
          <limit>
            <cfm>0</cfm>
            <erp>0.2</erp>
          </limit>
          <suspension>
            <cfm>0</cfm>
            <erp>0.2</erp>
          </suspension>
        </ode>
      </physics>
	</joint>

	<joint name='mw-j4' type='revolute'>
	  <pose>0 0 0 0 0 0</pose>
	  <parent>mecanum-base</parent>
	  <child>mw-l4</child>
	  <axis>
	    <xyz>0 1 0</xyz>
        <use_parent_model_frame>0</use_parent_model_frame>
        <limit>
          <lower>-1.79769e+308</lower>
          <upper>1.79769e+308</upper>
          <effort>-1</effort>
          <velocity>-1</velocity>
        </limit>
        <dynamics>
          <spring_reference>0</spring_reference>
          <spring_stiffness>0</spring_stiffness>
          <damping>0</damping>
          <friction>0</friction>
        </dynamics>
	  </axis>
      <physics>
        <ode>
          <limit>
            <cfm>0</cfm>
            <erp>0.2</erp>
          </limit>
          <suspension>
            <cfm>0</cfm>
            <erp>0.2</erp>
          </suspension>
        </ode>
      </physics>
	</joint>

	<joint name='mwj5' type='revolute'>
	  <pose>0 0 0 0 0 0</pose>
	  <parent>mecanum-base</parent>
	  <child>mw-l5</child>
	  <axis>
	    <xyz>0 1 0</xyz>
        <use_parent_model_frame>0</use_parent_model_frame>
        <limit>
          <lower>-1.79769e+308</lower>
          <upper>1.79769e+308</upper>
          <effort>-1</effort>
          <velocity>-1</velocity>
        </limit>
        <dynamics>
          <spring_reference>0</spring_reference>
          <spring_stiffness>0</spring_stiffness>
          <damping>0</damping>
          <friction>0</friction>
        </dynamics>
	  </axis>
      <physics>
        <ode>
          <limit>
            <cfm>0</cfm>
            <erp>0.2</erp>
          </limit>
          <suspension>
            <cfm>0</cfm>
            <erp>0.2</erp>
          </suspension>
        </ode>
      </physics>
	</joint>

	<joint name='mw-j6' type='revolute'>
	  <pose>0 0 0 0 0 0</pose>
	  <parent>mecanum-base</parent>
	  <child>mw-l6</child>
	  <axis>
	    <xyz>0 1 0</xyz>
        <use_parent_model_frame>0</use_parent_model_frame>
        <limit>
          <lower>-1.79769e+308</lower>
          <upper>1.79769e+308</upper>
          <effort>-1</effort>
          <velocity>-1</velocity>
        </limit>
        <dynamics>
          <spring_reference>0</spring_reference>
          <spring_stiffness>0</spring_stiffness>
          <damping>0</damping>
          <friction>0</friction>
        </dynamics>
	  </axis>
      <physics>
        <ode>
          <limit>
            <cfm>0</cfm>
            <erp>0.2</erp>
          </limit>
          <suspension>
            <cfm>0</cfm>
            <erp>0.2</erp>
          </suspension>
        </ode>
      </physics>
	</joint>

	<joint name='mw-j7' type='revolute'>
	  <pose>0 0 0 0 0 0</pose>
	  <parent>mecanum-base</parent>
	  <child>mw-l7</child>
	  <axis>
	    <xyz>0 1 0</xyz>
        <use_parent_model_frame>0</use_parent_model_frame>
        <limit>
          <lower>-1.79769e+308</lower>
          <upper>1.79769e+308</upper>
          <effort>-1</effort>
          <velocity>-1</velocity>
        </limit>
        <dynamics>
          <spring_reference>0</spring_reference>
          <spring_stiffness>0</spring_stiffness>
          <damping>0</damping>
          <friction>0</friction>
        </dynamics>
	  </axis>
      <physics>
        <ode>
          <limit>
            <cfm>0</cfm>
            <erp>0.2</erp>
          </limit>
          <suspension>
            <cfm>0</cfm>
            <erp>0.2</erp>
          </suspension>
        </ode>
      </physics>
	</joint>

	<joint name='mw-j8' type='revolute'>
	  <pose>0 0 0 0 0 0</pose>
	  <parent>mecanum-base</parent>
	  <child>mw-l8</child>
	  <axis>
	    <xyz>0 1 0</xyz>
        <use_parent_model_frame>0</use_parent_model_frame>
        <limit>
          <lower>-1.79769e+308</lower>
          <upper>1.79769e+308</upper>
          <effort>-1</effort>
          <velocity>-1</velocity>
        </limit>
        <dynamics>
          <spring_reference>0</spring_reference>
          <spring_stiffness>0</spring_stiffness>
          <damping>0</damping>
          <friction>0</friction>
        </dynamics>
	  </axis>
      <physics>
        <ode>
          <limit>
            <cfm>0</cfm>
            <erp>0.2</erp>
          </limit>
          <suspension>
            <cfm>0</cfm>
            <erp>0.2</erp>
          </suspension>
        </ode>
      </physics>
	</joint>

  </model>
</sdf>
